<?xml version="1.0" ?>
<!-- =================================================================================== -->
<!-- |    This document was autogenerated by xacro from robot_vtwo.xacro               | -->
<!-- |    EDITING THIS FILE BY HAND IS NOT RECOMMENDED                                 | -->
<!-- =================================================================================== -->
<robot name="chitti_vtwo">
  <material name="blue">
    <color rgba="0 0 1 1"/>
  </material>
  <material name="white">
    <color rgba="1 1 1 1"/>
  </material>
  <material name="black">
    <color rgba="0 0 0 1"/>
  </material>
  <material name="black_2">
    <color rgba="0 0 0 0.9"/>
  </material>
  <material name="yellow">
    <color rgba="1 1 0 1"/>
  </material>
  <gazebo>
    <plugin filename="gz-sim-diff-drive-system" name="gz::sim::systems::DiffDrive">
      <left_joint>wheel3_joint</left_joint>
      <left_joint>wheel4_joint</left_joint>
      <right_joint>wheel1_joint</right_joint>
      <right_joint>wheel2_joint</right_joint>
      <wheel_separation>0.5</wheel_separation>
      <wheel_radius>0.05</wheel_radius>
      <topic>/police/cmd_vel</topic>
    </plugin>
  </gazebo>
  <gazebo reference="pols_camera">
    <sensor name="camera" type="camera">
      <pose>0 0 0 0 0 0</pose>
      <always_on>true</always_on>
      <update_rate>30.0</update_rate>
      <visualize>true</visualize>
      <topic>/police/camera/image</topic>
      <camera>
        <horizontal_fov>1.089</horizontal_fov>
        <image>
          <width>640</width>
          <height>480</height>
          <format>R8G8B8</format>
        </image>
        <clip>
          <near>0.05</near>
          <far>8.0</far>
        </clip>
      </camera>
    </sensor>
  </gazebo>
  <link name="base_link">
    <inertial>
      <mass value="1.0"/>
      <origin rpy="0 0 0" xyz="0 0 0"/>
      <inertia ixx="0.001" ixy="0" ixz="0" iyy="0.001" iyz="0" izz="0.001"/>
    </inertial>
    <visual>
      <geometry>
        <cylinder length="0.6" radius="0.2"/>
      </geometry>
      <material name="blue"/>
    </visual>
    <collision>
      <geometry>
        <cylinder length="0.6" radius="0.2"/>
      </geometry>
    </collision>
  </link>
  <link name="pols_camera">
    <inertial>
      <mass value="0.05"/>
      <origin rpy="0 0 0" xyz="0 0 0"/>
      <inertia ixx="5e-05" ixy="0" ixz="0" iyy="5e-05" iyz="0" izz="5e-05"/>
    </inertial>
    <visual>
      <geometry>
        <sphere radius="0.05"/>
      </geometry>
      <material name="white"/>
    </visual>
    <collision>
      <geometry>
        <sphere radius="0.05"/>
      </geometry>
    </collision>
  </link>
  <joint name="ceye_joint" type="fixed">
    <parent link="base_link"/>
    <child link="pols_camera"/>
    <origin rpy="0 0 0" xyz="0.2 0 0"/>
  </joint>
  <link name="leg_l">
    <inertial>
      <mass value="1.0"/>
      <origin rpy="0 0 0" xyz="0 0 0"/>
      <inertia ixx="0.001" ixy="0" ixz="0" iyy="0.001" iyz="0" izz="0.001"/>
    </inertial>
    <visual>
      <geometry>
        <box size="0.6 0.1 0.2"/>
      </geometry>
      <material name="white"/>
    </visual>
    <collision>
      <geometry>
        <box size="0.6 0.1 0.2"/>
      </geometry>
    </collision>
  </link>
  <joint name="leg_joint_l" type="fixed">
    <parent link="base_link"/>
    <child link="leg_l"/>
    <origin rpy="0 1.570796326795 0" xyz="0 -0.25 -0.1"/>
  </joint>
  <link name="pad_l">
    <inertial>
      <mass value="5.0"/>
      <origin rpy="0 0 0" xyz="0 0 0"/>
      <inertia ixx="0.005" ixy="0" ixz="0" iyy="0.005" iyz="0" izz="0.005"/>
    </inertial>
    <visual>
      <geometry>
        <box size="0.4 0.15 0.1"/>
      </geometry>
      <material name="blue"/>
    </visual>
    <collision>
      <geometry>
        <box size="0.4 0.15 0.1"/>
      </geometry>
    </collision>
  </link>
  <joint name="pad_joint_l" type="fixed">
    <parent link="leg_l"/>
    <child link="pad_l"/>
    <origin rpy="0 -1.570796326795 0" xyz="0.35 0 0"/>
  </joint>
  <link name="leg_r">
    <inertial>
      <mass value="1.0"/>
      <origin rpy="0 0 0" xyz="0 0 0"/>
      <inertia ixx="0.001" ixy="0" ixz="0" iyy="0.001" iyz="0" izz="0.001"/>
    </inertial>
    <visual>
      <geometry>
        <box size="0.6 0.1 0.2"/>
      </geometry>
      <material name="white"/>
    </visual>
    <collision>
      <geometry>
        <box size="0.6 0.1 0.2"/>
      </geometry>
    </collision>
  </link>
  <joint name="leg_joint_r" type="fixed">
    <parent link="base_link"/>
    <child link="leg_r"/>
    <origin rpy="0 1.570796326795 0" xyz="0 0.25 -0.1"/>
  </joint>
  <link name="pad_r">
    <inertial>
      <mass value="5.0"/>
      <origin rpy="0 0 0" xyz="0 0 0"/>
      <inertia ixx="0.005" ixy="0" ixz="0" iyy="0.005" iyz="0" izz="0.005"/>
    </inertial>
    <visual>
      <geometry>
        <box size="0.4 0.15 0.1"/>
      </geometry>
      <material name="blue"/>
    </visual>
    <collision>
      <geometry>
        <box size="0.4 0.15 0.1"/>
      </geometry>
    </collision>
  </link>
  <joint name="pad_joint_r" type="fixed">
    <parent link="leg_r"/>
    <child link="pad_r"/>
    <origin rpy="0 -1.570796326795 0" xyz="0.35 0 0"/>
  </joint>
  <link name="wheel1">
    <inertial>
      <mass value="3.0"/>
      <origin rpy="0 0 0" xyz="0 0 0"/>
      <inertia ixx="0.003" ixy="0" ixz="0" iyy="0.003" iyz="0" izz="0.003"/>
    </inertial>
    <visual>
      <geometry>
        <cylinder length="0.1" radius="0.05"/>
      </geometry>
      <material name="black_2"/>
    </visual>
    <collision>
      <geometry>
        <cylinder length="0.1" radius="0.05"/>
      </geometry>
    </collision>
  </link>
  <joint name="wheel1_joint" type="continuous">
    <parent link="pad_l"/>
    <child link="wheel1"/>
    <origin rpy="1.570796326795 0 0" xyz="0.15 0 -0.1"/>
    <axis xyz="0 0 -1"/>
  </joint>
  <link name="iwheel1">
    <inertial>
      <mass value="2.0"/>
      <origin rpy="0 0 0" xyz="0 0 0"/>
      <inertia ixx="0.002" ixy="0" ixz="0" iyy="0.002" iyz="0" izz="0.002"/>
    </inertial>
    <visual>
      <geometry>
        <cylinder length="0.1" radius="0.025"/>
      </geometry>
      <material name="yellow"/>
    </visual>
    <collision>
      <geometry>
        <cylinder length="0.1" radius="0.025"/>
      </geometry>
    </collision>
  </link>
  <joint name="iwheel1_joint" type="fixed">
    <parent link="wheel1"/>
    <child link="iwheel1"/>
    <origin rpy="0 0 0" xyz="0 0 0"/>
  </joint>
  <link name="wheel2">
    <inertial>
      <mass value="3.0"/>
      <origin rpy="0 0 0" xyz="0 0 0"/>
      <inertia ixx="0.003" ixy="0" ixz="0" iyy="0.003" iyz="0" izz="0.003"/>
    </inertial>
    <visual>
      <geometry>
        <cylinder length="0.1" radius="0.05"/>
      </geometry>
      <material name="black_2"/>
    </visual>
    <collision>
      <geometry>
        <cylinder length="0.1" radius="0.05"/>
      </geometry>
    </collision>
  </link>
  <joint name="wheel2_joint" type="continuous">
    <parent link="pad_l"/>
    <child link="wheel2"/>
    <origin rpy="1.570796326795 0 0" xyz="-0.15 0 -0.1"/>
    <axis xyz="0 0 -1"/>
  </joint>
  <link name="iwheel2">
    <inertial>
      <mass value="2.0"/>
      <origin rpy="0 0 0" xyz="0 0 0"/>
      <inertia ixx="0.002" ixy="0" ixz="0" iyy="0.002" iyz="0" izz="0.002"/>
    </inertial>
    <visual>
      <geometry>
        <cylinder length="0.1" radius="0.025"/>
      </geometry>
      <material name="yellow"/>
    </visual>
    <collision>
      <geometry>
        <cylinder length="0.1" radius="0.025"/>
      </geometry>
    </collision>
  </link>
  <joint name="iwheel2_joint" type="fixed">
    <parent link="wheel2"/>
    <child link="iwheel2"/>
    <origin rpy="0 0 0" xyz="0 0 0"/>
  </joint>
  <link name="wheel3">
    <inertial>
      <mass value="3.0"/>
      <origin rpy="0 0 0" xyz="0 0 0"/>
      <inertia ixx="0.003" ixy="0" ixz="0" iyy="0.003" iyz="0" izz="0.003"/>
    </inertial>
    <visual>
      <geometry>
        <cylinder length="0.1" radius="0.05"/>
      </geometry>
      <material name="black_2"/>
    </visual>
    <collision>
      <geometry>
        <cylinder length="0.1" radius="0.05"/>
      </geometry>
    </collision>
  </link>
  <joint name="wheel3_joint" type="continuous">
    <parent link="pad_r"/>
    <child link="wheel3"/>
    <origin rpy="1.570796326795 0 0" xyz="-0.15 0 -0.1"/>
    <axis xyz="0 0 -1"/>
  </joint>
  <link name="iwheel3">
    <inertial>
      <mass value="2.0"/>
      <origin rpy="0 0 0" xyz="0 0 0"/>
      <inertia ixx="0.002" ixy="0" ixz="0" iyy="0.002" iyz="0" izz="0.002"/>
    </inertial>
    <visual>
      <geometry>
        <cylinder length="0.1" radius="0.025"/>
      </geometry>
      <material name="yellow"/>
    </visual>
    <collision>
      <geometry>
        <cylinder length="0.1" radius="0.025"/>
      </geometry>
    </collision>
  </link>
  <joint name="iwheel3_joint" type="fixed">
    <parent link="wheel3"/>
    <child link="iwheel3"/>
    <origin rpy="0 0 0" xyz="0 0 0"/>
  </joint>
  <link name="wheel4">
    <inertial>
      <mass value="3.0"/>
      <origin rpy="0 0 0" xyz="0 0 0"/>
      <inertia ixx="0.003" ixy="0" ixz="0" iyy="0.003" iyz="0" izz="0.003"/>
    </inertial>
    <visual>
      <geometry>
        <cylinder length="0.1" radius="0.05"/>
      </geometry>
      <material name="black_2"/>
    </visual>
    <collision>
      <geometry>
        <cylinder length="0.1" radius="0.05"/>
      </geometry>
    </collision>
  </link>
  <joint name="wheel4_joint" type="continuous">
    <parent link="pad_r"/>
    <child link="wheel4"/>
    <origin rpy="1.570796326795 0 0" xyz="0.15 0 -0.1"/>
    <axis xyz="0 0 -1"/>
  </joint>
  <link name="iwheel4">
    <inertial>
      <mass value="2.0"/>
      <origin rpy="0 0 0" xyz="0 0 0"/>
      <inertia ixx="0.002" ixy="0" ixz="0" iyy="0.002" iyz="0" izz="0.002"/>
    </inertial>
    <visual>
      <geometry>
        <cylinder length="0.1" radius="0.025"/>
      </geometry>
      <material name="yellow"/>
    </visual>
    <collision>
      <geometry>
        <cylinder length="0.1" radius="0.025"/>
      </geometry>
    </collision>
  </link>
  <joint name="iwheel4_joint" type="fixed">
    <parent link="wheel4"/>
    <child link="iwheel4"/>
    <origin rpy="0 0 0" xyz="0 0 0"/>
  </joint>
  <link name="head">
    <inertial>
      <mass value="0.5"/>
      <origin rpy="0 0 0" xyz="0 0 0"/>
      <inertia ixx="0.0005" ixy="0" ixz="0" iyy="0.0005" iyz="0" izz="0.0005"/>
    </inertial>
    <visual>
      <geometry>
        <sphere radius="0.2"/>
      </geometry>
      <material name="white"/>
    </visual>
    <collision>
      <geometry>
        <sphere radius="0.2"/>
      </geometry>
    </collision>
  </link>
  <joint name="head_joint1" type="continuous">
    <parent link="base_link"/>
    <child link="head"/>
    <origin rpy="0 0 0" xyz="0 0 0.3"/>
    <axis xyz="0 0 1"/>
  </joint>
  <link name="eye_socket">
    <inertial>
      <mass value="0.1"/>
      <origin rpy="0 0 0" xyz="0 0 0"/>
      <inertia ixx="0.0001" ixy="0" ixz="0" iyy="0.0001" iyz="0" izz="0.0001"/>
    </inertial>
    <visual>
      <geometry>
        <box size="0.1 0.1 0.1"/>
      </geometry>
      <material name="blue"/>
    </visual>
    <collision>
      <geometry>
        <box size="0.1 0.1 0.1"/>
      </geometry>
    </collision>
  </link>
  <joint name="eye_joint" type="fixed">
    <parent link="head"/>
    <child link="eye_socket"/>
    <origin rpy="0 0 0" xyz="0.1414 0 0.1414"/>
  </joint>
  <link name="eyeball">
    <inertial>
      <mass value="0.05"/>
      <origin rpy="0 0 0" xyz="0 0 0"/>
      <inertia ixx="5e-05" ixy="0" ixz="0" iyy="5e-05" iyz="0" izz="5e-05"/>
    </inertial>
    <visual>
      <geometry>
        <sphere radius="0.05"/>
      </geometry>
      <material name="white"/>
    </visual>
    <collision>
      <geometry>
        <sphere radius="0.05"/>
      </geometry>
    </collision>
  </link>
  <joint name="ieye_joint" type="revolute">
    <parent link="eye_socket"/>
    <child link="eyeball"/>
    <origin rpy="0 0 0" xyz="0.05 0 0"/>
    <axis xyz="0 1 0"/>
    <limit effort="100.0" lower="-1.570796326795" upper="1.570796326795" velocity="3.14"/>
  </joint>
  <link name="pupil">
    <inertial>
      <mass value="0.01"/>
      <origin rpy="0 0 0" xyz="0 0 0"/>
      <inertia ixx="1e-05" ixy="0" ixz="0" iyy="1e-05" iyz="0" izz="1e-05"/>
    </inertial>
    <visual>
      <geometry>
        <sphere radius="0.025"/>
      </geometry>
      <material name="black"/>
    </visual>
    <collision>
      <geometry>
        <sphere radius="0.025"/>
      </geometry>
    </collision>
  </link>
  <joint name="pupil_joint" type="fixed">
    <parent link="eyeball"/>
    <child link="pupil"/>
    <origin rpy="0 0 0" xyz="0.03 0 0"/>
  </joint>
</robot>
