<?xml version="1.0" ?>
<!-- =================================================================================== -->
<!-- |    This document was autogenerated by xacro from tuktuk.xacro                   | -->
<!-- |    EDITING THIS FILE BY HAND IS NOT RECOMMENDED                                 | -->
<!-- =================================================================================== -->
<robot name="tuktuk">
  <material name="blue">
    <color rgba="0 0 1 1"/>
  </material>
  <material name="white">
    <color rgba="1 1 1 1"/>
  </material>
  <material name="black">
    <color rgba="0 0 0 1"/>
  </material>
  <material name="black_2">
    <color rgba="0 0 0 0.95"/>
  </material>
  <material name="green">
    <color rgba="0 1 0 1"/>
  </material>
  <material name="red">
    <color rgba="1 0 0 1"/>
  </material>
  <material name="yellow">
    <color rgba="1 1 0 1"/>
  </material>
  <gazebo>
    <plugin filename="gz-sim-diff-drive-system" name="gz::sim::systems::DiffDrive">
      <left_joint>iwheell_joint</left_joint>
      <right_joint>iwheelr_joint</right_joint>
      <wheel_separation>0.7</wheel_separation>
      <wheel_radius>0.04</wheel_radius>
      <topic>/thief/cmd_vel</topic>
    </plugin>
  </gazebo>
  <gazebo reference="thief_camera">
    <sensor name="camera" type="camera">
      <pose>0 0 0 0 0 0</pose>
      <always_on>true</always_on>
      <update_rate>30.0</update_rate>
      <visualize>true</visualize>
      <topic>/thief/camera/image</topic>
      <camera>
        <horizontal_fov>1.089</horizontal_fov>
        <image>
          <width>640</width>
          <height>480</height>
          <format>R8G8B8</format>
        </image>
        <clip>
          <near>0.05</near>
          <far>8.0</far>
        </clip>
      </camera>
    </sensor>
  </gazebo>
  <link name="chassis">
    <inertial>
      <mass value="0.8"/>
      <origin rpy="0 0 0" xyz="0 0 0"/>
      <inertia ixx="0.024239999999999998" ixy="0" ixz="0" iyy="0.06690666666666667" iyz="0" izz="0.09066666666666666"/>
    </inertial>
    <visual>
      <geometry>
        <box size="1.0 0.6 0.06"/>
      </geometry>
      <material name="white"/>
    </visual>
    <collision>
      <geometry>
        <box size="1.0 0.6 0.06"/>
      </geometry>
    </collision>
  </link>
  <link name="stand">
    <inertial>
      <mass value="0.001"/>
      <origin rpy="0 0 0" xyz="0 0 0"/>
      <inertia ixx="0.001" ixy="0" ixz="0" iyy="0.001" iyz="0" izz="0.001"/>
    </inertial>
    <visual>
      <geometry>
        <cylinder length="0.5" radius="0.01"/>
      </geometry>
      <material name="white"/>
    </visual>
    <collision>
      <geometry>
        <cylinder length="0.5" radius="0.01"/>
      </geometry>
    </collision>
  </link>
  <joint name="stand_joint" type="fixed">
    <parent link="chassis"/>
    <child link="stand"/>
    <origin rpy="0 0 0" xyz="0 0 0.28"/>
  </joint>
  <link name="thief_camera">
    <inertial>
      <mass value="0.001"/>
      <origin rpy="0 0 0" xyz="0 0 0"/>
      <inertia ixx="0.001" ixy="0" ixz="0" iyy="0.001" iyz="0" izz="0.001"/>
    </inertial>
    <visual>
      <geometry>
        <sphere radius="0.05"/>
      </geometry>
      <material name="blue"/>
    </visual>
    <collision>
      <geometry>
        <sphere radius="0.06"/>
      </geometry>
    </collision>
  </link>
  <joint name="cam_joint" type="fixed">
    <parent link="stand"/>
    <child link="thief_camera"/>
    <origin rpy="0 0 0" xyz="0 0 0.25"/>
  </joint>
  <link name="ir1">
    <inertial>
      <mass value="0.01"/>
      <origin rpy="0 0 0" xyz="0 0 0"/>
      <inertia ixx="1.666666666666667e-05" ixy="0" ixz="0" iyy="1.666666666666667e-05" iyz="0" izz="1.666666666666667e-05"/>
    </inertial>
    <visual>
      <geometry>
        <box size="0.1 0.1 0.1"/>
      </geometry>
      <material name="blue"/>
    </visual>
    <collision>
      <geometry>
        <box size="0.1 0.1 0.1"/>
      </geometry>
    </collision>
  </link>
  <joint name="ir1_joint" type="fixed">
    <parent link="chassis"/>
    <child link="ir1"/>
    <origin rpy="0 0 0" xyz="0.45 0.25 0.08"/>
  </joint>
  <link name="ir2">
    <inertial>
      <mass value="0.01"/>
      <origin rpy="0 0 0" xyz="0 0 0"/>
      <inertia ixx="1.666666666666667e-05" ixy="0" ixz="0" iyy="1.666666666666667e-05" iyz="0" izz="1.666666666666667e-05"/>
    </inertial>
    <visual>
      <geometry>
        <box size="0.1 0.1 0.1"/>
      </geometry>
      <material name="blue"/>
    </visual>
    <collision>
      <geometry>
        <box size="0.1 0.1 0.1"/>
      </geometry>
    </collision>
  </link>
  <joint name="ir2_joint" type="fixed">
    <parent link="chassis"/>
    <child link="ir2"/>
    <origin rpy="0 0 0" xyz="0.45 0.1 0.08"/>
  </joint>
  <link name="ir3">
    <inertial>
      <mass value="0.01"/>
      <origin rpy="0 0 0" xyz="0 0 0"/>
      <inertia ixx="1.666666666666667e-05" ixy="0" ixz="0" iyy="1.666666666666667e-05" iyz="0" izz="1.666666666666667e-05"/>
    </inertial>
    <visual>
      <geometry>
        <box size="0.1 0.1 0.1"/>
      </geometry>
      <material name="blue"/>
    </visual>
    <collision>
      <geometry>
        <box size="0.1 0.1 0.1"/>
      </geometry>
    </collision>
  </link>
  <joint name="ir3_joint" type="fixed">
    <parent link="chassis"/>
    <child link="ir3"/>
    <origin rpy="0 0 0" xyz="0.45 -0.1 0.08"/>
  </joint>
  <link name="ir4">
    <inertial>
      <mass value="0.01"/>
      <origin rpy="0 0 0" xyz="0 0 0"/>
      <inertia ixx="1.666666666666667e-05" ixy="0" ixz="0" iyy="1.666666666666667e-05" iyz="0" izz="1.666666666666667e-05"/>
    </inertial>
    <visual>
      <geometry>
        <box size="0.1 0.1 0.1"/>
      </geometry>
      <material name="blue"/>
    </visual>
    <collision>
      <geometry>
        <box size="0.1 0.1 0.1"/>
      </geometry>
    </collision>
  </link>
  <joint name="ir4_joint" type="fixed">
    <parent link="chassis"/>
    <child link="ir4"/>
    <origin rpy="0 0 0" xyz="0.45 -0.25 0.08"/>
  </joint>
  <link name="irl">
    <inertial>
      <mass value="0.01"/>
      <origin rpy="0 0 0" xyz="0 0 0"/>
      <inertia ixx="1.666666666666667e-05" ixy="0" ixz="0" iyy="1.666666666666667e-05" iyz="0" izz="1.666666666666667e-05"/>
    </inertial>
    <visual>
      <geometry>
        <box size="0.1 0.1 0.1"/>
      </geometry>
      <material name="blue"/>
    </visual>
    <collision>
      <geometry>
        <box size="0.1 0.1 0.1"/>
      </geometry>
    </collision>
  </link>
  <joint name="irl_joint" type="fixed">
    <parent link="chassis"/>
    <child link="irl"/>
    <origin rpy="0 0 0" xyz="0.3 0.25 0.08"/>
  </joint>
  <link name="irr">
    <inertial>
      <mass value="0.01"/>
      <origin rpy="0 0 0" xyz="0 0 0"/>
      <inertia ixx="1.666666666666667e-05" ixy="0" ixz="0" iyy="1.666666666666667e-05" iyz="0" izz="1.666666666666667e-05"/>
    </inertial>
    <visual>
      <geometry>
        <box size="0.1 0.1 0.1"/>
      </geometry>
      <material name="blue"/>
    </visual>
    <collision>
      <geometry>
        <box size="0.1 0.1 0.1"/>
      </geometry>
    </collision>
  </link>
  <joint name="irr_joint" type="fixed">
    <parent link="chassis"/>
    <child link="irr"/>
    <origin rpy="0 0 0" xyz="0.3 -0.25 0.08"/>
  </joint>
  <link name="arduino">
    <inertial>
      <mass value="0.04"/>
      <origin rpy="0 0 0" xyz="0 0 0"/>
      <inertia ixx="0.00030833333333333337" ixy="0" ixz="0" iyy="0.00030833333333333337" iyz="0" izz="0.0006"/>
    </inertial>
    <visual>
      <geometry>
        <box size="0.3 0.3 0.05"/>
      </geometry>
      <material name="green"/>
    </visual>
    <collision>
      <geometry>
        <box size="0.3 0.3 0.05"/>
      </geometry>
    </collision>
  </link>
  <joint name="arduino_joint" type="fixed">
    <parent link="chassis"/>
    <child link="arduino"/>
    <origin rpy="0 0 0" xyz="0 0.15 0.055"/>
  </joint>
  <link name="driver">
    <inertial>
      <mass value="0.04"/>
      <origin rpy="0 0 0" xyz="0 0 0"/>
      <inertia ixx="0.00030833333333333337" ixy="0" ixz="0" iyy="0.00030833333333333337" iyz="0" izz="0.0006"/>
    </inertial>
    <visual>
      <geometry>
        <box size="0.3 0.3 0.05"/>
      </geometry>
      <material name="red"/>
    </visual>
    <collision>
      <geometry>
        <box size="0.3 0.3 0.05"/>
      </geometry>
    </collision>
  </link>
  <joint name="driver_joint" type="fixed">
    <parent link="chassis"/>
    <child link="driver"/>
    <origin rpy="0 0 0" xyz="0 -0.15 0.055"/>
  </joint>
  <link name="battery">
    <inertial>
      <mass value="0.35"/>
      <origin rpy="0 0 0" xyz="0 0 0"/>
      <inertia ixx="0.0049583333333333346" ixy="0" ixz="0" iyy="0.0014583333333333334" iyz="0" izz="0.005833333333333334"/>
    </inertial>
    <visual>
      <geometry>
        <box size="0.2 0.4 0.1"/>
      </geometry>
      <material name="black"/>
    </visual>
    <collision>
      <geometry>
        <box size="0.2 0.4 0.1"/>
      </geometry>
    </collision>
  </link>
  <joint name="battery_joint" type="fixed">
    <parent link="chassis"/>
    <child link="battery"/>
    <origin rpy="0 0 0" xyz="-0.4 0 0.075"/>
  </joint>
  <link name="switch">
    <inertial>
      <mass value="0.005"/>
      <origin rpy="0 0 0" xyz="0 0 0"/>
      <inertia ixx="9.47916666666667e-07" ixy="0" ixz="0" iyy="9.47916666666667e-07" iyz="0" izz="1.5625e-06"/>
    </inertial>
    <visual>
      <geometry>
        <cylinder length="0.02" radius="0.025"/>
      </geometry>
      <material name="black"/>
    </visual>
    <collision>
      <geometry>
        <cylinder length="0.02" radius="0.025"/>
      </geometry>
    </collision>
  </link>
  <joint name="switch_joint" type="fixed">
    <parent link="chassis"/>
    <child link="switch"/>
    <origin rpy="0 0 0" xyz="-0.4 0.25 0.04"/>
  </joint>
  <link name="caster_base">
    <inertial>
      <mass value="0.03"/>
      <origin rpy="0 0 0" xyz="0 0 0"/>
      <inertia ixx="5.424999999999999e-05" ixy="0" ixz="0" iyy="5.424999999999999e-05" iyz="0" izz="9.599999999999999e-05"/>
    </inertial>
    <visual>
      <geometry>
        <cylinder length="0.05" radius="0.08"/>
      </geometry>
      <material name="red"/>
    </visual>
    <collision>
      <geometry>
        <cylinder length="0.05" radius="0.08"/>
      </geometry>
    </collision>
  </link>
  <joint name="caster_joint" type="fixed">
    <parent link="chassis"/>
    <child link="caster_base"/>
    <origin rpy="0 0 0" xyz="0.4 0 -0.055"/>
  </joint>
  <link name="caster_stud">
    <inertial>
      <mass value="0.01"/>
      <origin rpy="0 0 0" xyz="0 0 0"/>
      <inertia ixx="6.895833333333335e-06" ixy="0" ixz="0" iyy="6.895833333333335e-06" iyz="0" izz="3.125e-06"/>
    </inertial>
    <visual>
      <geometry>
        <cylinder length="0.08" radius="0.025"/>
      </geometry>
      <material name="red"/>
    </visual>
    <collision>
      <geometry>
        <cylinder length="0.08" radius="0.025"/>
      </geometry>
    </collision>
  </link>
  <joint name="stud_joint" type="fixed">
    <parent link="caster_base"/>
    <child link="caster_stud"/>
    <origin rpy="0 0 0" xyz="0 0 -0.065"/>
  </joint>
  <link name="dummy_link1">
    <inertial>
      <mass value="0.001"/>
      <origin rpy="0 0 0" xyz="0 0 0"/>
      <inertia ixx="0.001" ixy="0" ixz="0" iyy="0.001" iyz="0" izz="0.001"/>
    </inertial>
    <collision>
      <geometry>
        <sphere radius="0"/>
      </geometry>
    </collision>
  </link>
  <link name="dummy_link2">
    <inertial>
      <mass value="0.001"/>
      <origin rpy="0 0 0" xyz="0 0 0"/>
      <inertia ixx="0.001" ixy="0" ixz="0" iyy="0.001" iyz="0" izz="0.001"/>
    </inertial>
    <collision>
      <geometry>
        <sphere radius="0"/>
      </geometry>
    </collision>
  </link>
  <link name="caster_ball">
    <inertial>
      <mass value="0.02"/>
      <origin rpy="0 0 0" xyz="0 0 0"/>
      <inertia ixx="5e-06" ixy="0" ixz="0" iyy="5e-06" iyz="0" izz="5e-06"/>
    </inertial>
    <visual>
      <geometry>
        <sphere radius="0.025"/>
      </geometry>
      <material name="black"/>
    </visual>
    <collision>
      <geometry>
        <sphere radius="0.025"/>
      </geometry>
    </collision>
  </link>
  <joint name="ball_n_socketx" type="continuous">
    <parent link="caster_stud"/>
    <child link="dummy_link1"/>
    <origin rpy="0 0 0" xyz="0 0 -0.04"/>
    <axis xyz="1 0 0"/>
  </joint>
  <joint name="ball_n_sockety" type="continuous">
    <parent link="dummy_link1"/>
    <child link="dummy_link2"/>
    <origin rpy="0 0 0" xyz="0 0 0"/>
    <axis xyz="0 1 0"/>
  </joint>
  <joint name="ball_n_socketz" type="continuous">
    <parent link="dummy_link2"/>
    <child link="caster_ball"/>
    <origin rpy="0 0 0" xyz="0 0 0"/>
    <axis xyz="0 0 1"/>
  </joint>
  <link name="motorl">
    <inertial>
      <mass value="0.12"/>
      <origin rpy="0 0 0" xyz="0 0 0"/>
      <inertia ixx="0.000325" ixy="0" ixz="0" iyy="0.0002" iyz="0" izz="0.000325"/>
    </inertial>
    <visual>
      <geometry>
        <box size="0.1 0.15 0.1"/>
      </geometry>
      <material name="blue"/>
    </visual>
    <collision>
      <geometry>
        <box size="0.1 0.15 0.1"/>
      </geometry>
    </collision>
  </link>
  <joint name="motorl_joint" type="fixed">
    <parent link="chassis"/>
    <child link="motorl"/>
    <origin rpy="0 0 0" xyz="-0.3 0.225 -0.08"/>
  </joint>
  <link name="iwheell">
    <inertial>
      <mass value="0.03"/>
      <origin rpy="0 0 0" xyz="0 0 0"/>
      <inertia ixx="4.3750000000000006e-05" ixy="0" ixz="0" iyy="4.3750000000000006e-05" iyz="0" izz="3.7500000000000003e-05"/>
    </inertial>
    <visual>
      <geometry>
        <cylinder length="0.1" radius="0.05"/>
      </geometry>
      <material name="yellow"/>
    </visual>
    <collision>
      <geometry>
        <cylinder length="0.1" radius="0.05"/>
      </geometry>
    </collision>
  </link>
  <joint name="iwheell_joint" type="continuous">
    <parent link="motorl"/>
    <child link="iwheell"/>
    <origin rpy="1.570796326795 0 0" xyz="0 0.125 0"/>
    <axis xyz="0 0 -1"/>
  </joint>
  <link name="wheell">
    <inertial>
      <mass value="0.08"/>
      <origin rpy="0 0 0" xyz="0 0 0"/>
      <inertia ixx="0.00026666666666666673" ixy="0" ixz="0" iyy="0.00026666666666666673" iyz="0" izz="0.0004"/>
    </inertial>
    <visual>
      <geometry>
        <cylinder length="0.1" radius="0.1"/>
      </geometry>
      <material name="black_2"/>
    </visual>
    <collision>
      <geometry>
        <cylinder length="0.1" radius="0.1"/>
      </geometry>
    </collision>
  </link>
  <joint name="wheell_joint" type="fixed">
    <parent link="iwheell"/>
    <child link="wheell"/>
    <origin rpy="0 0 0" xyz="0 0 0"/>
  </joint>
  <link name="motorr">
    <inertial>
      <mass value="0.12"/>
      <origin rpy="0 0 0" xyz="0 0 0"/>
      <inertia ixx="0.000325" ixy="0" ixz="0" iyy="0.0002" iyz="0" izz="0.000325"/>
    </inertial>
    <visual>
      <geometry>
        <box size="0.1 0.15 0.1"/>
      </geometry>
      <material name="blue"/>
    </visual>
    <collision>
      <geometry>
        <box size="0.1 0.15 0.1"/>
      </geometry>
    </collision>
  </link>
  <joint name="motorr_joint" type="fixed">
    <parent link="chassis"/>
    <child link="motorr"/>
    <origin rpy="0 0 0" xyz="-0.3 -0.225 -0.08"/>
  </joint>
  <link name="iwheelr">
    <inertial>
      <mass value="0.03"/>
      <origin rpy="0 0 0" xyz="0 0 0"/>
      <inertia ixx="4.3750000000000006e-05" ixy="0" ixz="0" iyy="4.3750000000000006e-05" iyz="0" izz="3.7500000000000003e-05"/>
    </inertial>
    <visual>
      <geometry>
        <cylinder length="0.1" radius="0.05"/>
      </geometry>
      <material name="yellow"/>
    </visual>
    <collision>
      <geometry>
        <cylinder length="0.1" radius="0.05"/>
      </geometry>
    </collision>
  </link>
  <joint name="iwheelr_joint" type="continuous">
    <parent link="motorr"/>
    <child link="iwheelr"/>
    <origin rpy="1.570796326795 0 0" xyz="0 -0.125 0"/>
    <axis xyz="0 0 -1"/>
  </joint>
  <link name="wheelr">
    <inertial>
      <mass value="0.08"/>
      <origin rpy="0 0 0" xyz="0 0 0"/>
      <inertia ixx="0.00026666666666666673" ixy="0" ixz="0" iyy="0.00026666666666666673" iyz="0" izz="0.0004"/>
    </inertial>
    <visual>
      <geometry>
        <cylinder length="0.1" radius="0.1"/>
      </geometry>
      <material name="black_2"/>
    </visual>
    <collision>
      <geometry>
        <cylinder length="0.1" radius="0.1"/>
      </geometry>
    </collision>
  </link>
  <joint name="wheelr_joint" type="fixed">
    <parent link="iwheelr"/>
    <child link="wheelr"/>
    <origin rpy="0 0 0" xyz="0 0 0"/>
  </joint>
</robot>
